{
    "issue": {
        "title": "UnicodeEncodeError for column name in pandas_compat.py",
        "body": "***Note**: This issue was originally created as [ARROW-1981](https://issues.apache.org/jira/browse/ARROW-1981). Please see the [migration documentation](https://gist.github.com/toddfarmer/12aa88361532d21902818a6044fda4c3) for further details.*\n\n### Original Issue Description:\n[Related code](https://github.com/apache/arrow/blob/ee134f0e4b285e17f33a56e7750836dd82a13735/python/pyarrow/pandas_compat.py#L139-#L179)\r\n\r\n{{\r\nTraceback (most recent call last):\r\n  File \"project/folder/file.py\", line 34, in <module>\r\n    main()\r\n  File \"/opt/conda/lib/python2.7/site-packages/click/core.py\", line 722, in __call__\r\n    return self.main(\\*args, \\*\\*kwargs)\r\n  File \"/opt/conda/lib/python2.7/site-packages/click/core.py\", line 697, in main\r\n    rv = self.invoke(ctx)\r\n  File \"/opt/conda/lib/python2.7/site-packages/click/core.py\", line 895, in invoke\r\n    return ctx.invoke(self.callback, \\*\\*ctx.params)\r\n  File \"/opt/conda/lib/python2.7/site-packages/click/core.py\", line 535, in invoke\r\n    return callback(\\*args, \\*\\*kwargs)\r\n  File \"project/folder/file.py\", line 29, in main\r\n    df.to_parquet(pq_filename)\r\n  File \"/opt/conda/lib/python2.7/site-packages/pandas/core/frame.py\", line 1649, in to_parquet\r\n    compression=compression, \\*\\*kwargs)\r\n  File \"/opt/conda/lib/python2.7/site-packages/pandas/io/parquet.py\", line 178, in to_parquet\r\n    return impl.write(df, path, compression=compression)\r\n  File \"/opt/conda/lib/python2.7/site-packages/pandas/io/parquet.py\", line 74, in write\r\n    table = self.api.Table.from_pandas(df)\r\n  File \"pyarrow/table.pxi\", line 875, in pyarrow.lib.Table.from_pandas (/arrow/python/build/temp.linux-x86_64-2.7/lib.cxx:44927)\r\n  File \"/opt/conda/lib/python2.7/site-packages/pyarrow/pandas_compat.py\", line 361, in dataframe_to_arrays\r\n    df, names, index_columns, preserve_index, types\r\n  File \"/opt/conda/lib/python2.7/site-packages/pyarrow/pandas_compat.py\", line 211, in construct_metadata\r\n    df.columns, column_names, df_types\r\n  File \"/opt/conda/lib/python2.7/site-packages/pyarrow/pandas_compat.py\", line 175, in get_column_metadata\r\n    'field_name': str(field_name),\r\nUnicodeEncodeError: 'ascii' codec can't encode character u'\\xe9' in position 31: ordinal not in range(128)\r\n}}",
        "created_at": "2018-01-10T10:16:54.000Z",
        "updated_at": "2018-01-13T07:27:03.000Z",
        "labels": [
            "Migrated from Jira",
            "Component: Python",
            "Type: bug"
        ],
        "closed": true,
        "closed_at": "2018-01-13T07:27:03.000Z"
    },
    "comments": [
        {
            "created_at": "2018-01-10T14:29:43.279Z",
            "body": "***Note**: [Comment](https://issues.apache.org/jira/browse/ARROW-1981?focusedCommentId=16320324) by Simbarashe Nyatsanga (simbanyatsanga):*\nI think this is related to this issue: https://issues.apache.org/jira/browse/ARROW-1976"
        }
    ]
}