{
    "issue": {
        "title": "[Python] test_unicode_filename test fails when unicode filenames aren't supported by system",
        "body": "***Note**: This issue was originally created as [ARROW-1088](https://issues.apache.org/jira/browse/ARROW-1088). Please see the [migration documentation](https://gist.github.com/toddfarmer/12aa88361532d21902818a6044fda4c3) for further details.*\n\n### Original Issue Description:\nBuilding/running pyarrow in Docker using Ubuntu 17.04 as a base (with no other modification) fails `test_unicode_filename` as unicode filenames are apparently not supported by default in this setup. This is further confirmed by the value of `os.path.supports_unicode_filenames = False`. This test should be skipped in such situations.",
        "created_at": "2017-06-03T11:27:43.000Z",
        "updated_at": "2017-06-06T20:52:14.000Z",
        "labels": [
            "Migrated from Jira",
            "Component: Python",
            "Type: bug"
        ],
        "closed": true,
        "closed_at": "2017-06-06T20:51:57.000Z"
    },
    "comments": [
        {
            "created_at": "2017-06-03T12:02:49.963Z",
            "body": "***Note**: [Comment](https://issues.apache.org/jira/browse/ARROW-1088?focusedCommentId=16035953) by Jeff Knupp (jeffknupp):*\nAddressed in https://github.com/apache/arrow/pull/727"
        },
        {
            "created_at": "2017-06-04T19:51:24.827Z",
            "body": "***Note**: [Comment](https://issues.apache.org/jira/browse/ARROW-1088?focusedCommentId=16036374) by Uwe Korn (uwe):*\nFrom my understanding, it should not fail due to the filename. While `supports_unicode_filenames = False`\u00a0this should only mean that the encoding is not respected but on Linux systems, you should be able to use any bytes for a filename. `[~jeffknupp]` What is the exact failure you get?"
        },
        {
            "created_at": "2017-06-04T21:09:04.907Z",
            "body": "***Note**: [Comment](https://issues.apache.org/jira/browse/ARROW-1088?focusedCommentId=16036395) by Jeff Knupp (jeffknupp):*\nWell, the issue is that functions like `os.stat` and `os.remove` are indirectly called on the file (which, of course, can be any bytes for the name itself within Python). Below is the traceback output:\n\n```Java\nroot@183bbfdb623a:/home/ubuntu/arrow/arrow/python# py.test pyarrow\n==================================================================== test session starts ====================================================================\nplatform linux -- Python 3.5.3, pytest-3.1.1, py-1.4.33, pluggy-0.4.0\nrootdir: /home/ubuntu/arrow/arrow/python, inifile: setup.cfg\ncollected 185 items / 2 skipped\n\npyarrow/tests/test_array.py ...........\npyarrow/tests/test_convert_builtin.py ......................\npyarrow/tests/test_convert_pandas.py ............................x....\npyarrow/tests/test_deprecations.py ..\npyarrow/tests/test_feather.py .......................x..FE.\npyarrow/tests/test_io.py ..................\npyarrow/tests/test_ipc.py .............x\npyarrow/tests/test_jemalloc.py ..\npyarrow/tests/test_scalars.py ..........\npyarrow/tests/test_schema.py ..............\npyarrow/tests/test_table.py ...............\npyarrow/tests/test_tensor.py ................\n\n========================================================================== ERRORS ===========================================================================\n_______________________________________________ ERROR at teardown of TestFeatherReader.test_unicode_filename ________________________________________________\n\nself = <pyarrow.tests.test_feather.TestFeatherReader testMethod=test_unicode_filename>\n\n    def tearDown(self):\n        for path in self.test_files:\n            try:\n>               os.remove(path)\nE               UnicodeEncodeError: 'ascii' codec can't encode character '\\xeb' in position 10: ordinal not in range(128)\n\npyarrow/tests/test_feather.py:45: UnicodeEncodeError\n========================================================================= FAILURES ==========================================================================\n__________________________________________________________ TestFeatherReader.test_unicode_filename __________________________________________________________\n\nself = <pyarrow.tests.test_feather.TestFeatherReader testMethod=test_unicode_filename>\n\n    def test_unicode_filename(self):\n# GH #209\n        name = (b'Besa_Kavaj\\xc3\\xab.feather').decode('utf-8')\n        df = pd.DataFrame({'foo': [1, 2, 3, 4]})\n>       self._check_pandas_roundtrip(df, path=name)\n\npyarrow/tests/test_feather.py:362:\n_ _ _ _ _ _ _ _ _ _ _ _ _ _ _ _ _ _ _ _ _ _ _ _ _ _ _ _ _ _ _ _ _ _ _ _ _ _ _ _ _ _ _ _ _ _ _ _ _ _ _ _ _ _ _ _ _ _ _ _ _ _ _ _ _ _ _ _ _ _ _ _ _ _ _ _ _ _ _\npyarrow/tests/test_feather.py:71: in _check_pandas_roundtrip\n    if not os.path.exists(path):\n_ _ _ _ _ _ _ _ _ _ _ _ _ _ _ _ _ _ _ _ _ _ _ _ _ _ _ _ _ _ _ _ _ _ _ _ _ _ _ _ _ _ _ _ _ _ _ _ _ _ _ _ _ _ _ _ _ _ _ _ _ _ _ _ _ _ _ _ _ _ _ _ _ _ _ _ _ _ _\n\npath = 'Besa_Kavaj\\xeb.feather'\n\n    def exists(path):\n        \"\"\"Test whether a path exists.  Returns False for broken symbolic links\"\"\"\n        try:\n>           os.stat(path)\nE           UnicodeEncodeError: 'ascii' codec can't encode character '\\xeb' in position 10: ordinal not in range(128)\n\n/usr/lib/python3.5/genericpath.py:19: UnicodeEncodeError\n```"
        },
        {
            "created_at": "2017-06-06T20:51:57.635Z",
            "body": "***Note**: [Comment](https://issues.apache.org/jira/browse/ARROW-1088?focusedCommentId=16039609) by Wes McKinney (wesm):*\nIssue resolved by pull request 727\n<https://github.com/apache/arrow/pull/727>"
        }
    ]
}